import { TaskRunner } from "~/runner";
import { createMockEvent } from "~tests/mocks";
import { ResponseErrorResult } from "~/response";
import { TaskDataStatus } from "~/types";
import { createLiveContextFactory } from "~tests/live";
import { taskDefinition } from "~tests/runner/taskDefinition";
import { timerFactory } from "@webiny/handler-aws/utils";
import { TaskEventValidation } from "~/runner/TaskEventValidation";

describe("task runner error in failed state", () => {
    const contextFactory = createLiveContextFactory({
        plugins: [taskDefinition]
    });

    it("should trigger a task run - error because task is already in failed state", async () => {
        const context = await contextFactory();

        const runner = new TaskRunner(context, timerFactory(), new TaskEventValidation());

        const task = await context.tasks.createTask({
            definitionId: taskDefinition.id,
            input: {},
            name: "My task name"
        });
        const updatedTask = await context.tasks.updateTask(task.id, {
            taskStatus: TaskDataStatus.FAILED
        });

        const result = await runner.run(
            createMockEvent({
                webinyTaskId: updatedTask.id,
                webinyTaskDefinitionId: taskDefinition.id
            })
        );
        expect(result).toBeInstanceOf(ResponseErrorResult);
        expect(result).toEqual({
            status: "error",
            webinyTaskId: updatedTask.id,
            webinyTaskDefinitionId: taskDefinition.id,
            tenant: "root",
            locale: "en-US",
            error: {
                message: "Task has failed, cannot run it again."
            }
        });
    });
});
